Workbook

Sheet 設定
A1: 為替レート設定（必要に応じて数値を書き換えてください）
A3: 1 GBP = | B3: 216 | C3: 円
A4: 1 EUR = | B4: 185 | C4: 円

Sheet 統合決済履歴
A1: 日付 | B1: 摘要（加盟店等） | C1: 金額 | D1: 通貨 | E1: 種別 | F1: ステータス | G1: カテゴリ | H1: 残高 | I1: 取引元ファイル | J1: 集計対象 | K1: 年月
A2: 2026-09-30 | B2: Uber | C2: -19.15 | D2: EUR | E2: カード決済 | F2: COMPLETED | G2: Transport | I2: exported-activities.pdf（Wiseカード） | J2: 共通 | K2: =TEXT(A2,"YYYY-MM")
A3: 2026-09-30 | B3: MAYA MORIさんへの送金（Uber差額分！） | C3: -1.6 | D3: EUR | E3: 送金/入出金 | F3: COMPLETED | G3: General | H3: 18.26 | I3: account-statement_2026-09-01_2026-09-30_ja-jp_ec3fc3.pdf（Revolut） | J3: 共通 | K3: =TEXT(A3,"YYYY-MM")
A4: 2026-09-30 | B4: KAZUHIRO SHIGEMOTOさんからの送金 | C4: 4.79 | D4: EUR | E4: 送金/入出金 | F4: COMPLETED | G4: Money added | H4: 19.86 | I4: account-statement_2026-09-01_2026-09-30_ja-jp_ec3fc3.pdf（Revolut） | J4: 共通 | K4: =TEXT(A4,"YYYY-MM")
A5: 2026-09-28 | B5: Espace Lavage | C5: -10 | D5: EUR | E5: カード決済 | F5: COMPLETED | G5: Bills | I5: exported-activities.pdf（Wiseカード） | J5: 共通 | K5: =TEXT(A5,"YYYY-MM")
A6: 2026-09-26 | B6: MASAHIRO KAWAMURAさんからの送金（タクシー代） | C6: 15 | D6: EUR | E6: 送金/入出金 | F6: COMPLETED | G6: Money added | H6: 15.07 | I6: account-statement_2026-09-01_2026-09-30_ja-jp_ec3fc3.pdf（Revolut） | J6: 共通 | K6: =TEXT(A6,"YYYY-MM")
A7: 2026-09-26 | B7: MASAHIRO KAWAHATAさんへの送金 | C7: -30 | D7: EUR | E7: 送金/入出金 | F7: COMPLETED | G7: General | H7: 0.07 | I7: account-statement_2026-09-01_2026-09-30_ja-jp_ec3fc3.pdf（Revolut） | J7: 共通 | K7: =TEXT(A7,"YYYY-MM")
A8: 2026-09-26 | B8: AIRI HASUOさんからの送金（Uber） | C8: 15 | D8: EUR | E8: 送金/入出金 | F8: COMPLETED | G8: Money added | H8: 30.07 | I8: account-statement_2026-09-01_2026-09-30_ja-jp_ec3fc3.pdf（Revolut） | J8: 共通 | K8: =TEXT(A8,"YYYY-MM")
A9: 2026-09-26 | B9: TAKAHIRO YAMASHITAさんからの送金 | C9: 15 | D9: EUR | E9: 送金/入出金 | F9: COMPLETED | G9: Money added | H9: 15.07 | I9: account-statement_2026-09-01_2026-09-30_ja-jp_ec3fc3.pdf（Revolut） | J9: 共通 | K9: =TEXT(A9,"YYYY-MM")
A10: 2026-09-26 | B10: L ARCHESTE | C10: -426 | D10: EUR | E10: カード決済 | F10: COMPLETED | G10: Eating out | I10: meisai_20261003212728842.pdf（SMBC信託銀行カード） | J10: 共通 | K10: =TEXT(A10,"YYYY-MM")
A11: 2026-09-26 | B11: SC-CAFE FLORE | C11: -17 | D11: EUR | E11: カード決済 | F11: COMPLETED | G11: Eating out | H11: 94.29 | I11: meisai_20261003212728842.pdf（SMBC信託銀行カード） | J11: 共通 | K11: =TEXT(A11,"YYYY-MM")
A12: 2026-09-26 | B12: TLC | C12: -34.5 | D12: EUR | E12: カード決済 | F12: COMPLETED | G12: Transport | I12: meisai_20261003212728842.pdf（SMBC信託銀行カード） | J12: 共通 | K12: =TEXT(A12,"YYYY-MM")
A13: 2026-09-25 | B13: Uber | C13: -58.98 | D13: EUR | E13: カード決済 | F13: COMPLETED | G13: Transport | I13: exported-activities.pdf（Wiseカード） | J13: 共通 | K13: =TEXT(A13,"YYYY-MM")
A14: 2026-09-25 | B14: Moved to EUR (100 GBP) | C14: 115.81 | D14: EUR | E14: 送金/入出金 | F14: COMPLETED | G14: Money added | I14: exported-activities.pdf（Wiseカード） | J14: 共通 | K14: =TEXT(A14,"YYYY-MM")
A15: 2026-09-25 | B15: Hec Resto | C15: -20 | D15: EUR | E15: カード決済 | F15: COMPLETED | G15: Family | I15: exported-activities.pdf（Wiseカード） | J15: 共通 | K15: =TEXT(A15,"YYYY-MM")
A16: 2026-09-23 | B16: Bureau Des Ele | C16: -6 | D16: EUR | E16: カード決済 | F16: COMPLETED | G16: Shopping | I16: exported-activities.pdf（Wiseカード） | J16: 共通 | K16: =TEXT(A16,"YYYY-MM")
A17: 2026-09-23 | B17: Auchan | C17: -116 | D17: EUR | E17: カード決済 | F17: COMPLETED | G17: Shopping | I17: exported-activities.pdf（Wiseカード） | J17: 共通 | K17: =TEXT(A17,"YYYY-MM")
A18: 2026-09-23 | B18: THOMAS GUICHEMERREさんへの送金 | C18: -20 | D18: EUR | E18: 送金/入出金 | F18: COMPLETED | G18: General | H18: 0.07 | I18: account-statement_2026-09-01_2026-09-30_ja-jp_ec3fc3.pdf（Revolut） | J18: 共通 | K18: =TEXT(A18,"YYYY-MM")
A19: 2026-09-22 | B19: Moved to EUR (100 GBP) | C19: 116.16 | D19: EUR | E19: 送金/入出金 | F19: COMPLETED | G19: Money added | I19: exported-activities.pdf（Wiseカード） | J19: 共通 | K19: =TEXT(A19,"YYYY-MM")
A20: 2026-09-22 | B20: MASAHIRO KAWAHATAさんからの送金 | C20: 10.74 | D20: EUR | E20: 送金/入出金 | F20: COMPLETED | G20: Money added | H20: 20.07 | I20: account-statement_2026-09-01_2026-09-30_ja-jp_ec3fc3.pdf（Revolut） | J20: 共通 | K20: =TEXT(A20,"YYYY-MM")
A21: 2026-09-21 | B21: KAZUMA USUIさんへの送金 | C21: -14.86 | D21: EUR | E21: 送金/入出金 | F21: COMPLETED | G21: General | H21: 9.33 | I21: account-statement_2026-09-01_2026-09-30_ja-jp_ec3fc3.pdf（Revolut） | J21: 共通 | K21: =TEXT(A21,"YYYY-MM")
A22: 2026-09-21 | B22: MASAHIRO KAWAMURAさんからの送金 | C22: 7.71 | D22: EUR | E22: 送金/入出金 | F22: COMPLETED | G22: Money added | H22: 24.19 | I22: account-statement_2026-09-01_2026-09-30_ja-jp_ec3fc3.pdf（Revolut） | J22: 共通 | K22: =TEXT(A22,"YYYY-MM")
A23: 2026-09-21 | B23: 紹介報酬 | C23: 10 | D23: EUR | E23: 送金/入出金 | F23: COMPLETED | G23: Money added | H23: 16.48 | I23: account-statement_2026-09-01_2026-09-30_ja-jp_ec3fc3.pdf（Revolut） | J23: 共通 | K23: =TEXT(A23,"YYYY-MM")
A24: 2026-09-21 | B24: Uber | C24: -42.93 | D24: EUR | E24: カード決済 | F24: COMPLETED | G24: Transport | H24: 6.48 | I24: account-statement_2026-09-01_2026-09-30_ja-jp_ec3fc3.pdf（Revolut） | J24: 共通 | K24: =TEXT(A24,"YYYY-MM")
A25: 2026-09-20 | B25: Amazon Pay | C25: -18.99 | D25: EUR | E25: カード決済 | F25: COMPLETED | G25: Shopping | I25: exported-activities.pdf（Wiseカード） | J25: 共通 | K25: =TEXT(A25,"YYYY-MM")
A26: 2026-09-20 | B26: SOLA RAMEN | C26: -15 | D26: EUR | E26: カード決済 | F26: COMPLETED | G26: Eating out | I26: meisai_20261003212728842.pdf（SMBC信託銀行カード） | J26: 共通 | K26: =TEXT(A26,"YYYY-MM")
A27: 2026-09-20 | B27: BOULANGERIE ZES | C27: -6.5 | D27: EUR | E27: カード決済 | F27: COMPLETED | G27: Groceries | I27: meisai_20261003212728842.pdf（SMBC信託銀行カード） | J27: 共通 | K27: =TEXT(A27,"YYYY-MM")
A28: 2026-09-19 | B28: Ace Mart | C28: -88.55 | D28: EUR | E28: カード決済 | F28: COMPLETED | G28: Groceries | I28: exported-activities.pdf（Wiseカード） | J28: 共通 | K28: =TEXT(A28,"YYYY-MM")
A29: 2026-09-19 | B29: IKEA | C29: -1.5 | D29: EUR | E29: カード決済 | F29: COMPLETED | G29: Shopping | I29: exported-activities.pdf（Wiseカード） | J29: 共通 | K29: =TEXT(A29,"YYYY-MM")
A30: 2026-09-19 | B30: IKEA | C30: -48.88 | D30: EUR | E30: カード決済 | F30: COMPLETED | G30: Shopping | I30: exported-activities.pdf（Wiseカード） | J30: 共通 | K30: =TEXT(A30,"YYYY-MM")
A31: 2026-09-19 | B31: Momola Pigalle.t2pay | C31: -10 | D31: EUR | E31: カード決済 | F31: COMPLETED | G31: Eating out | I31: exported-activities.pdf（Wiseカード） | J31: 共通 | K31: =TEXT(A31,"YYYY-MM")
A32: 2026-09-19 | B32: Kow | C32: -6 | D32: EUR | E32: カード決済 | F32: COMPLETED | G32: Eating out | I32: exported-activities.pdf（Wiseカード） | J32: 共通 | K32: =TEXT(A32,"YYYY-MM")
A33: 2026-09-19 | B33: 4M2 Mymasgwc | C33: -10 | D33: EUR | E33: カード決済 | F33: COMPLETED | G33: Groceries | I33: exported-activities.pdf（Wiseカード） | J33: 共通 | K33: =TEXT(A33,"YYYY-MM")
A34: 2026-09-19 | B34: Snp Usagi Delice | C34: -10 | D34: EUR | E34: カード決済 | F34: COMPLETED | G34: Eating out | I34: exported-activities.pdf（Wiseカード） | J34: 共通 | K34: =TEXT(A34,"YYYY-MM")
A35: 2026-09-19 | B35: IDF Mobilités | Navigo pass | C35: -25.5 | D35: EUR | E35: カード決済 | F35: COMPLETED | G35: Transport | H35: 136.54 | I35: exported-activities.pdf（Wiseカード） | J35: 共通 | K35: =TEXT(A35,"YYYY-MM")
A36: 2026-09-19 | B36: IDF Mobilités | Navigo pass | C36: -25.5 | D36: EUR | E36: カード決済 | F36: COMPLETED | G36: Transport | I36: exported-activities.pdf（Wiseカード） | J36: 共通 | K36: =TEXT(A36,"YYYY-MM")
A37: 2026-09-19 | B37: IDF Mobilités | Navigo pass | C37: -20.5 | D37: EUR | E37: カード決済 | F37: COMPLETED | G37: Transport | I37: exported-activities.pdf（Wiseカード） | J37: 共通 | K37: =TEXT(A37,"YYYY-MM")
A38: 2026-09-19 | B38: IDF Mobilités | Navigo pass | C38: -20.5 | D38: EUR | E38: カード決済 | F38: COMPLETED | G38: Transport | I38: exported-activities.pdf（Wiseカード） | J38: 共通 | K38: =TEXT(A38,"YYYY-MM")
A39: 2026-09-19 | B39: SHUN KINOSHITAさんからの送金 | C39: 5 | D39: EUR | E39: 送金/入出金 | F39: COMPLETED | G39: Money added | H39: 49.41 | I39: account-statement_2026-09-01_2026-09-30_ja-jp_ec3fc3.pdf（Revolut） | J39: 共通 | K39: =TEXT(A39,"YYYY-MM")
A40: 2026-09-17 | B40: Auchan | C40: -24 | D40: EUR | E40: カード決済 | F40: COMPLETED | G40: Shopping | I40: exported-activities.pdf（Wiseカード） | J40: 共通 | K40: =TEXT(A40,"YYYY-MM")
...

Sheet 月別集計
A1: 2026年9月
A3: ■ 聖也
A4: カテゴリ | B4: GBP 合計 | C4: EUR 合計 | D4: JPY 合計 | E4: JPY換算合計
A5: Bills | B5: =SUMIFS(統合決済履歴!$C$2:$C$198,統合決済履歴!$G$2:$G$198,"Bills",統合決済履歴!$D$2:$D$198,"GBP",統合決済履歴!$F$2:$F$198,"COMPLETED",統合決済履歴!$J$2:$J$198,"聖也",統合決済履歴!$K$2:$K$198,"2026-09") | C5: =SUMIFS(統合決済履歴!$C$2:$C$198,統合決済履歴!$G$2:$G$198,"Bills",統合決済履歴!$D$2:$D$198,"EUR",統合決済履歴!$F$2:$F$198,"COMPLETED",統合決済履歴!$J$2:$J$198,"聖也",統合決済履歴!$K$2:$K$198,"2026-09") | D5: =SUMIFS(統合決済履歴!$C$2:$C$198,統合決済履歴!$G$2:$G$198,"Bills",統合決済履歴!$D$2:$D$198,"JPY",統合決済履歴!$F$2:$F$198,"COMPLETED",統合決済履歴!$J$2:$J$198,"聖也",統合決済履歴!$K$2:$K$198,"2026-09") | E5: =B5*設定!$B$3+C5*設定!$B$4+D5
A6: Eating out | B6: =SUMIFS(統合決済履歴!$C$2:$C$198,統合決済履歴!$G$2:$G$198,"Eating out",統合決済履歴!$D$2:$D$198,"GBP",統合決済履歴!$F$2:$F$198,"COMPLETED",統合決済履歴!$J$2:$J$198,"聖也",統合決済履歴!$K$2:$K$198,"2026-09") | C6: =SUMIFS(統合決済履歴!$C$2:$C$198,統合決済履歴!$G$2:$G$198,"Eating out",統合決済履歴!$D$2:$D$198,"EUR",統合決済履歴!$F$2:$F$198,"COMPLETED",統合決済履歴!$J$2:$J$198,"聖也",統合決済履歴!$K$2:$K$198,"2026-09") | D6: =SUMIFS(統合決済履歴!$C$2:$C$198,統合決済履歴!$G$2:$G$198,"Eating out",統合決済履歴!$D$2:$D$198,"JPY",統合決済履歴!$F$2:$F$198,"COMPLETED",統合決済履歴!$J$2:$J$198,"聖也",統合決済履歴!$K$2:$K$198,"2026-09") | E6: =B6*設定!$B$3+C6*設定!$B$4+D6
A7: Entertainment | B7: =SUMIFS(統合決済履歴!$C$2:$C$198,統合決済履歴!$G$2:$G$198,"Entertainment",統合決済履歴!$D$2:$D$198,"GBP",統合決済履歴!$F$2:$F$198,"COMPLETED",統合決済履歴!$J$2:$J$198,"聖也",統合決済履歴!$K$2:$K$198,"2026-09") | C7: =SUMIFS(統合決済履歴!$C$2:$C$198,統合決済履歴!$G$2:$G$198,"Entertainment",統合決済履歴!$D$2:$D$198,"EUR",統合決済履歴!$F$2:$F$198,"COMPLETED",統合決済履歴!$J$2:$J$198,"聖也",統合決済履歴!$K$2:$K$198,"2026-09") | D7: =SUMIFS(統合決済履歴!$C$2:$C$198,統合決済履歴!$G$2:$G$198,"Entertainment",統合決済履歴!$D$2:$D$198,"JPY",統合決済履歴!$F$2:$F$198,"COMPLETED",統合決済履歴!$J$2:$J$198,"聖也",統合決済履歴!$K$2:$K$198,"2026-09") | E7: =B7*設定!$B$3+C7*設定!$B$4+D7
A8: Family | B8: =SUMIFS(統合決済履歴!$C$2:$C$198,統合決済履歴!$G$2:$G$198,"Family",統合決済履歴!$D$2:$D$198,"GBP",統合決済履歴!$F$2:$F$198,"COMPLETED",統合決済履歴!$J$2:$J$198,"聖也",統合決済履歴!$K$2:$K$198,"2026-09") | C8: =SUMIFS(統合決済履歴!$C$2:$C$198,統合決済履歴!$G$2:$G$198,"Family",統合決済履歴!$D$2:$D$198,"EUR",統合決済履歴!$F$2:$F$198,"COMPLETED",統合決済履歴!$J$2:$J$198,"聖也",統合決済履歴!$K$2:$K$198,"2026-09") | D8: =SUMIFS(統合決済履歴!$C$2:$C$198,統合決済履歴!$G$2:$G$198,"Family",統合決済履歴!$D$2:$D$198,"JPY",統合決済履歴!$F$2:$F$198,"COMPLETED",統合決済履歴!$J$2:$J$198,"聖也",統合決済履歴!$K$2:$K$198,"2026-09") | E8: =B8*設定!$B$3+C8*設定!$B$4+D8
A9: General | B9: =SUMIFS(統合決済履歴!$C$2:$C$198,統合決済履歴!$G$2:$G$198,"General",統合決済履歴!$D$2:$D$198,"GBP",統合決済履歴!$F$2:$F$198,"COMPLETED",統合決済履歴!$J$2:$J$198,"聖也",統合決済履歴!$K$2:$K$198,"2026-09") | C9: =SUMIFS(統合決済履歴!$C$2:$C$198,統合決済履歴!$G$2:$G$198,"General",統合決済履歴!$D$2:$D$198,"EUR",統合決済履歴!$F$2:$F$198,"COMPLETED",統合決済履歴!$J$2:$J$198,"聖也",統合決済履歴!$K$2:$K$198,"2026-09") | D9: =SUMIFS(統合決済履歴!$C$2:$C$198,統合決済履歴!$G$2:$G$198,"General",統合決済履歴!$D$2:$D$198,"JPY",統合決済履歴!$F$2:$F$198,"COMPLETED",統合決済履歴!$J$2:$J$198,"聖也",統合決済履歴!$K$2:$K$198,"2026-09") | E9: =B9*設定!$B$3+C9*設定!$B$4+D9
A10: Groceries | B10: =SUMIFS(統合決済履歴!$C$2:$C$198,統合決済履歴!$G$2:$G$198,"Groceries",統合決済履歴!$D$2:$D$198,"GBP",統合決済履歴!$F$2:$F$198,"COMPLETED",統合決済履歴!$J$2:$J$198,"聖也",統合決済履歴!$K$2:$K$198,"2026-09") | C10: =SUMIFS(統合決済履歴!$C$2:$C$198,統合決済履歴!$G$2:$G$198,"Groceries",統合決済履歴!$D$2:$D$198,"EUR",統合決済履歴!$F$2:$F$198,"COMPLETED",統合決済履歴!$J$2:$J$198,"聖也",統合決済履歴!$K$2:$K$198,"2026-09") | D10: =SUMIFS(統合決済履歴!$C$2:$C$198,統合決済履歴!$G$2:$G$198,"Groceries",統合決済履歴!$D$2:$D$198,"JPY",統合決済履歴!$F$2:$F$198,"COMPLETED",統合決済履歴!$J$2:$J$198,"聖也",統合決済履歴!$K$2:$K$198,"2026-09") | E10: =B10*設定!$B$3+C10*設定!$B$4+D10
A11: Money added | B11: =SUMIFS(統合決済履歴!$C$2:$C$198,統合決済履歴!$G$2:$G$198,"Money added",統合決済履歴!$D$2:$D$198,"GBP",統合決済履歴!$F$2:$F$198,"COMPLETED",統合決済履歴!$J$2:$J$198,"聖也",統合決済履歴!$K$2:$K$198,"2026-09") | C11: =SUMIFS(統合決済履歴!$C$2:$C$198,統合決済履歴!$G$2:$G$198,"Money added",統合決済履歴!$D$2:$D$198,"EUR",統合決済履歴!$F$2:$F$198,"COMPLETED",統合決済履歴!$J$2:$J$198,"聖也",統合決済履歴!$K$2:$K$198,"2026-09") | D11: =SUMIFS(統合決済履歴!$C$2:$C$198,統合決済履歴!$G$2:$G$198,"Money added",統合決済履歴!$D$2:$D$198,"JPY",統合決済履歴!$F$2:$F$198,"COMPLETED",統合決済履歴!$J$2:$J$198,"聖也",統合決済履歴!$K$2:$K$198,"2026-09") | E11: =B11*設定!$B$3+C11*設定!$B$4+D11
A12: Personal care | B12: =SUMIFS(統合決済履歴!$C$2:$C$198,統合決済履歴!$G$2:$G$198,"Personal care",統合決済履歴!$D$2:$D$198,"GBP",統合決済履歴!$F$2:$F$198,"COMPLETED",統合決済履歴!$J$2:$J$198,"聖也",統合決済履歴!$K$2:$K$198,"2026-09") | C12: =SUMIFS(統合決済履歴!$C$2:$C$198,統合決済履歴!$G$2:$G$198,"Personal care",統合決済履歴!$D$2:$D$198,"EUR",統合決済履歴!$F$2:$F$198,"COMPLETED",統合決済履歴!$J$2:$J$198,"聖也",統合決済履歴!$K$2:$K$198,"2026-09") | D12: =SUMIFS(統合決済履歴!$C$2:$C$198,統合決済履歴!$G$2:$G$198,"Personal care",統合決済履歴!$D$2:$D$198,"JPY",統合決済履歴!$F$2:$F$198,"COMPLETED",統合決済履歴!$J$2:$J$198,"聖也",統合決済履歴!$K$2:$K$198,"2026-09") | E12: =B12*設定!$B$3+C12*設定!$B$4+D12
A13: Shopping | B13: =SUMIFS(統合決済履歴!$C$2:$C$198,統合決済履歴!$G$2:$G$198,"Shopping",統合決済履歴!$D$2:$D$198,"GBP",統合決済履歴!$F$2:$F$198,"COMPLETED",統合決済履歴!$J$2:$J$198,"聖也",統合決済履歴!$K$2:$K$198,"2026-09") | C13: =SUMIFS(統合決済履歴!$C$2:$C$198,統合決済履歴!$G$2:$G$198,"Shopping",統合決済履歴!$D$2:$D$198,"EUR",統合決済履歴!$F$2:$F$198,"COMPLETED",統合決済履歴!$J$2:$J$198,"聖也",統合決済履歴!$K$2:$K$198,"2026-09") | D13: =SUMIFS(統合決済履歴!$C$2:$C$198,統合決済履歴!$G$2:$G$198,"Shopping",統合決済履歴!$D$2:$D$198,"JPY",統合決済履歴!$F$2:$F$198,"COMPLETED",統合決済履歴!$J$2:$J$198,"聖也",統合決済履歴!$K$2:$K$198,"2026-09") | E13: =B13*設定!$B$3+C13*設定!$B$4+D13
A14: Transport | B14: =SUMIFS(統合決済履歴!$C$2:$C$198,統合決済履歴!$G$2:$G$198,"Transport",統合決済履歴!$D$2:$D$198,"GBP",統合決済履歴!$F$2:$F$198,"COMPLETED",統合決済履歴!$J$2:$J$198,"聖也",統合決済履歴!$K$2:$K$198,"2026-09") | C14: =SUMIFS(統合決済履歴!$C$2:$C$198,統合決済履歴!$G$2:$G$198,"Transport",統合決済履歴!$D$2:$D$198,"EUR",統合決済履歴!$F$2:$F$198,"COMPLETED",統合決済履歴!$J$2:$J$198,"聖也",統合決済履歴!$K$2:$K$198,"2026-09") | D14: =SUMIFS(統合決済履歴!$C$2:$C$198,統合決済履歴!$G$2:$G$198,"Transport",統合決済履歴!$D$2:$D$198,"JPY",統合決済履歴!$F$2:$F$198,"COMPLETED",統合決済履歴!$J$2:$J$198,"聖也",統合決済履歴!$K$2:$K$198,"2026-09") | E14: =B14*設定!$B$3+C14*設定!$B$4+D14
A15: 合計 | B15: =SUM(B5:B14) | C15: =SUM(C5:C14) | D15: =SUM(D5:D14) | E15: =SUM(E5:E14)
A17: ■ 愛弓
A18: カテゴリ | B18: GBP 合計 | C18: EUR 合計 | D18: JPY 合計 | E18: JPY換算合計
A19: Bills | B19: =SUMIFS(統合決済履歴!$C$2:$C$198,統合決済履歴!$G$2:$G$198,"Bills",統合決済履歴!$D$2:$D$198,"GBP",統合決済履歴!$F$2:$F$198,"COMPLETED",統合決済履歴!$J$2:$J$198,"愛弓",統合決済履歴!$K$2:$K$198,"2026-09") | C19: =SUMIFS(統合決済履歴!$C$2:$C$198,統合決済履歴!$G$2:$G$198,"Bills",統合決済履歴!$D$2:$D$198,"EUR",統合決済履歴!$F$2:$F$198,"COMPLETED",統合決済履歴!$J$2:$J$198,"愛弓",統合決済履歴!$K$2:$K$198,"2026-09") | D19: =SUMIFS(統合決済履歴!$C$2:$C$198,統合決済履歴!$G$2:$G$198,"Bills",統合決済履歴!$D$2:$D$198,"JPY",統合決済履歴!$F$2:$F$198,"COMPLETED",統合決済履歴!$J$2:$J$198,"愛弓",統合決済履歴!$K$2:$K$198,"2026-09") | E19: =B19*設定!$B$3+C19*設定!$B$4+D19
A20: Eating out | B20: =SUMIFS(統合決済履歴!$C$2:$C$198,統合決済履歴!$G$2:$G$198,"Eating out",統合決済履歴!$D$2:$D$198,"GBP",統合決済履歴!$F$2:$F$198,"COMPLETED",統合決済履歴!$J$2:$J$198,"愛弓",統合決済履歴!$K$2:$K$198,"2026-09") | C20: =SUMIFS(統合決済履歴!$C$2:$C$198,統合決済履歴!$G$2:$G$198,"Eating out",統合決済履歴!$D$2:$D$198,"EUR",統合決済履歴!$F$2:$F$198,"COMPLETED",統合決済履歴!$J$2:$J$198,"愛弓",統合決済履歴!$K$2:$K$198,"2026-09") | D20: =SUMIFS(統合決済履歴!$C$2:$C$198,統合決済履歴!$G$2:$G$198,"Eating out",統合決済履歴!$D$2:$D$198,"JPY",統合決済履歴!$F$2:$F$198,"COMPLETED",統合決済履歴!$J$2:$J$198,"愛弓",統合決済履歴!$K$2:$K$198,"2026-09") | E20: =B20*設定!$B$3+C20*設定!$B$4+D20
A21: Entertainment | B21: =SUMIFS(統合決済履歴!$C$2:$C$198,統合決済履歴!$G$2:$G$198,"Entertainment",統合決済履歴!$D$2:$D$198,"GBP",統合決済履歴!$F$2:$F$198,"COMPLETED",統合決済履歴!$J$2:$J$198,"愛弓",統合決済履歴!$K$2:$K$198,"2026-09") | C21: =SUMIFS(統合決済履歴!$C$2:$C$198,統合決済履歴!$G$2:$G$198,"Entertainment",統合決済履歴!$D$2:$D$198,"EUR",統合決済履歴!$F$2:$F$198,"COMPLETED",統合決済履歴!$J$2:$J$198,"愛弓",統合決済履歴!$K$2:$K$198,"2026-09") | D21: =SUMIFS(統合決済履歴!$C$2:$C$198,統合決済履歴!$G$2:$G$198,"Entertainment",統合決済履歴!$D$2:$D$198,"JPY",統合決済履歴!$F$2:$F$198,"COMPLETED",統合決済履歴!$J$2:$J$198,"愛弓",統合決済履歴!$K$2:$K$198,"2026-09") | E21: =B21*設定!$B$3+C21*設定!$B$4+D21
A22: Family | B22: =SUMIFS(統合決済履歴!$C$2:$C$198,統合決済履歴!$G$2:$G$198,"Family",統合決済履歴!$D$2:$D$198,"GBP",統合決済履歴!$F$2:$F$198,"COMPLETED",統合決済履歴!$J$2:$J$198,"愛弓",統合決済履歴!$K$2:$K$198,"2026-09") | C22: =SUMIFS(統合決済履歴!$C$2:$C$198,統合決済履歴!$G$2:$G$198,"Family",統合決済履歴!$D$2:$D$198,"EUR",統合決済履歴!$F$2:$F$198,"COMPLETED",統合決済履歴!$J$2:$J$198,"愛弓",統合決済履歴!$K$2:$K$198,"2026-09") | D22: =SUMIFS(統合決済履歴!$C$2:$C$198,統合決済履歴!$G$2:$G$198,"Family",統合決済履歴!$D$2:$D$198,"JPY",統合決済履歴!$F$2:$F$198,"COMPLETED",統合決済履歴!$J$2:$J$198,"愛弓",統合決済履歴!$K$2:$K$198,"2026-09") | E22: =B22*設定!$B$3+C22*設定!$B$4+D22
A23: General | B23: =SUMIFS(統合決済履歴!$C$2:$C$198,統合決済履歴!$G$2:$G$198,"General",統合決済履歴!$D$2:$D$198,"GBP",統合決済履歴!$F$2:$F$198,"COMPLETED",統合決済履歴!$J$2:$J$198,"愛弓",統合決済履歴!$K$2:$K$198,"2026-09") | C23: =SUMIFS(統合決済履歴!$C$2:$C$198,統合決済履歴!$G$2:$G$198,"General",統合決済履歴!$D$2:$D$198,"EUR",統合決済履歴!$F$2:$F$198,"COMPLETED",統合決済履歴!$J$2:$J$198,"愛弓",統合決済履歴!$K$2:$K$198,"2026-09") | D23: =SUMIFS(統合決済履歴!$C$2:$C$198,統合決済履歴!$G$2:$G$198,"General",統合決済履歴!$D$2:$D$198,"JPY",統合決済履歴!$F$2:$F$198,"COMPLETED",統合決済履歴!$J$2:$J$198,"愛弓",統合決済履歴!$K$2:$K$198,"2026-09") | E23: =B23*設定!$B$3+C23*設定!$B$4+D23
A24: Groceries | B24: =SUMIFS(統合決済履歴!$C$2:$C$198,統合決済履歴!$G$2:$G$198,"Groceries",統合決済履歴!$D$2:$D$198,"GBP",統合決済履歴!$F$2:$F$198,"COMPLETED",統合決済履歴!$J$2:$J$198,"愛弓",統合決済履歴!$K$2:$K$198,"2026-09") | C24: =SUMIFS(統合決済履歴!$C$2:$C$198,統合決済履歴!$G$2:$G$198,"Groceries",統合決済履歴!$D$2:$D$198,"EUR",統合決済履歴!$F$2:$F$198,"COMPLETED",統合決済履歴!$J$2:$J$198,"愛弓",統合決済履歴!$K$2:$K$198,"2026-09") | D24: =SUMIFS(統合決済履歴!$C$2:$C$198,統合決済履歴!$G$2:$G$198,"Groceries",統合決済履歴!$D$2:$D$198,"JPY",統合決済履歴!$F$2:$F$198,"COMPLETED",統合決済履歴!$J$2:$J$198,"愛弓",統合決済履歴!$K$2:$K$198,"2026-09") | E24: =B24*設定!$B$3+C24*設定!$B$4+D24
A25: Money added | B25: =SUMIFS(統合決済履歴!$C$2:$C$198,統合決済履歴!$G$2:$G$198,"Money added",統合決済履歴!$D$2:$D$198,"GBP",統合決済履歴!$F$2:$F$198,"COMPLETED",統合決済履歴!$J$2:$J$198,"愛弓",統合決済履歴!$K$2:$K$198,"2026-09") | C25: =SUMIFS(統合決済履歴!$C$2:$C$198,統合決済履歴!$G$2:$G$198,"Money added",統合決済履歴!$D$2:$D$198,"EUR",統合決済履歴!$F$2:$F$198,"COMPLETED",統合決済履歴!$J$2:$J$198,"愛弓",統合決済履歴!$K$2:$K$198,"2026-09") | D25: =SUMIFS(統合決済履歴!$C$2:$C$198,統合決済履歴!$G$2:$G$198,"Money added",統合決済履歴!$D$2:$D$198,"JPY",統合決済履歴!$F$2:$F$198,"COMPLETED",統合決済履歴!$J$2:$J$198,"愛弓",統合決済履歴!$K$2:$K$198,"2026-09") | E25: =B25*設定!$B$3+C25*設定!$B$4+D25
A26: Personal care | B26: =SUMIFS(統合決済履歴!$C$2:$C$198,統合決済履歴!$G$2:$G$198,"Personal care",統合決済履歴!$D$2:$D$198,"GBP",統合決済履歴!$F$2:$F$198,"COMPLETED",統合決済履歴!$J$2:$J$198,"愛弓",統合決済履歴!$K$2:$K$198,"2026-09") | C26: =SUMIFS(統合決済履歴!$C$2:$C$198,統合決済履歴!$G$2:$G$198,"Personal care",統合決済履歴!$D$2:$D$198,"EUR",統合決済履歴!$F$2:$F$198,"COMPLETED",統合決済履歴!$J$2:$J$198,"愛弓",統合決済履歴!$K$2:$K$198,"2026-09") | D26: =SUMIFS(統合決済履歴!$C$2:$C$198,統合決済履歴!$G$2:$G$198,"Personal care",統合決済履歴!$D$2:$D$198,"JPY",統合決済履歴!$F$2:$F$198,"COMPLETED",統合決済履歴!$J$2:$J$198,"愛弓",統合決済履歴!$K$2:$K$198,"2026-09") | E26: =B26*設定!$B$3+C26*設定!$B$4+D26
A27: Shopping | B27: =SUMIFS(統合決済履歴!$C$2:$C$198,統合決済履歴!$G$2:$G$198,"Shopping",統合決済履歴!$D$2:$D$198,"GBP",統合決済履歴!$F$2:$F$198,"COMPLETED",統合決済履歴!$J$2:$J$198,"愛弓",統合決済履歴!$K$2:$K$198,"2026-09") | C27: =SUMIFS(統合決済履歴!$C$2:$C$198,統合決済履歴!$G$2:$G$198,"Shopping",統合決済履歴!$D$2:$D$198,"EUR",統合決済履歴!$F$2:$F$198,"COMPLETED",統合決済履歴!$J$2:$J$198,"愛弓",統合決済履歴!$K$2:$K$198,"2026-09") | D27: =SUMIFS(統合決済履歴!$C$2:$C$198,統合決済履歴!$G$2:$G$198,"Shopping",統合決済履歴!$D$2:$D$198,"JPY",統合決済履歴!$F$2:$F$198,"COMPLETED",統合決済履歴!$J$2:$J$198,"愛弓",統合決済履歴!$K$2:$K$198,"2026-09") | E27: =B27*設定!$B$3+C27*設定!$B$4+D27
A28: Transport | B28: =SUMIFS(統合決済履歴!$C$2:$C$198,統合決済履歴!$G$2:$G$198,"Transport",統合決済履歴!$D$2:$D$198,"GBP",統合決済履歴!$F$2:$F$198,"COMPLETED",統合決済履歴!$J$2:$J$198,"愛弓",統合決済履歴!$K$2:$K$198,"2026-09") | C28: =SUMIFS(統合決済履歴!$C$2:$C$198,統合決済履歴!$G$2:$G$198,"Transport",統合決済履歴!$D$2:$D$198,"EUR",統合決済履歴!$F$2:$F$198,"COMPLETED",統合決済履歴!$J$2:$J$198,"愛弓",統合決済履歴!$K$2:$K$198,"2026-09") | D28: =SUMIFS(統合決済履歴!$C$2:$C$198,統合決済履歴!$G$2:$G$198,"Transport",統合決済履歴!$D$2:$D$198,"JPY",統合決済履歴!$F$2:$F$198,"COMPLETED",統合決済履歴!$J$2:$J$198,"愛弓",統合決済履歴!$K$2:$K$198,"2026-09") | E28: =B28*設定!$B$3+C28*設定!$B$4+D28
A29: 合計 | B29: =SUM(B19:B28) | C29: =SUM(C19:C28) | D29: =SUM(D19:D28) | E29: =SUM(E19:E28)
A31: ■ 共通
A32: カテゴリ | B32: GBP 合計 | C32: EUR 合計 | D32: JPY 合計 | E32: JPY換算合計
A33: Bills | B33: =SUMIFS(統合決済履歴!$C$2:$C$198,統合決済履歴!$G$2:$G$198,"Bills",統合決済履歴!$D$2:$D$198,"GBP",統合決済履歴!$F$2:$F$198,"COMPLETED",統合決済履歴!$J$2:$J$198,"共通",統合決済履歴!$K$2:$K$198,"2026-09") | C33: =SUMIFS(統合決済履歴!$C$2:$C$198,統合決済履歴!$G$2:$G$198,"Bills",統合決済履歴!$D$2:$D$198,"EUR",統合決済履歴!$F$2:$F$198,"COMPLETED",統合決済履歴!$J$2:$J$198,"共通",統合決済履歴!$K$2:$K$198,"2026-09") | D33: =SUMIFS(統合決済履歴!$C$2:$C$198,統合決済履歴!$G$2:$G$198,"Bills",統合決済履歴!$D$2:$D$198,"JPY",統合決済履歴!$F$2:$F$198,"COMPLETED",統合決済履歴!$J$2:$J$198,"共通",統合決済履歴!$K$2:$K$198,"2026-09") | E33: =B33*設定!$B$3+C33*設定!$B$4+D33
A34: Eating out | B34: =SUMIFS(統合決済履歴!$C$2:$C$198,統合決済履歴!$G$2:$G$198,"Eating out",統合決済履歴!$D$2:$D$198,"GBP",統合決済履歴!$F$2:$F$198,"COMPLETED",統合決済履歴!$J$2:$J$198,"共通",統合決済履歴!$K$2:$K$198,"2026-09") | C34: =SUMIFS(統合決済履歴!$C$2:$C$198,統合決済履歴!$G$2:$G$198,"Eating out",統合決済履歴!$D$2:$D$198,"EUR",統合決済履歴!$F$2:$F$198,"COMPLETED",統合決済履歴!$J$2:$J$198,"共通",統合決済履歴!$K$2:$K$198,"2026-09") | D34: =SUMIFS(統合決済履歴!$C$2:$C$198,統合決済履歴!$G$2:$G$198,"Eating out",統合決済履歴!$D$2:$D$198,"JPY",統合決済履歴!$F$2:$F$198,"COMPLETED",統合決済履歴!$J$2:$J$198,"共通",統合決済履歴!$K$2:$K$198,"2026-09") | E34: =B34*設定!$B$3+C34*設定!$B$4+D34
A35: Entertainment | B35: =SUMIFS(統合決済履歴!$C$2:$C$198,統合決済履歴!$G$2:$G$198,"Entertainment",統合決済履歴!$D$2:$D$198,"GBP",統合決済履歴!$F$2:$F$198,"COMPLETED",統合決済履歴!$J$2:$J$198,"共通",統合決済履歴!$K$2:$K$198,"2026-09") | C35: =SUMIFS(統合決済履歴!$C$2:$C$198,統合決済履歴!$G$2:$G$198,"Entertainment",統合決済履歴!$D$2:$D$198,"EUR",統合決済履歴!$F$2:$F$198,"COMPLETED",統合決済履歴!$J$2:$J$198,"共通",統合決済履歴!$K$2:$K$198,"2026-09") | D35: =SUMIFS(統合決済履歴!$C$2:$C$198,統合決済履歴!$G$2:$G$198,"Entertainment",統合決済履歴!$D$2:$D$198,"JPY",統合決済履歴!$F$2:$F$198,"COMPLETED",統合決済履歴!$J$2:$J$198,"共通",統合決済履歴!$K$2:$K$198,"2026-09") | E35: =B35*設定!$B$3+C35*設定!$B$4+D35
A36: Family | B36: =SUMIFS(統合決済履歴!$C$2:$C$198,統合決済履歴!$G$2:$G$198,"Family",統合決済履歴!$D$2:$D$198,"GBP",統合決済履歴!$F$2:$F$198,"COMPLETED",統合決済履歴!$J$2:$J$198,"共通",統合決済履歴!$K$2:$K$198,"2026-09") | C36: =SUMIFS(統合決済履歴!$C$2:$C$198,統合決済履歴!$G$2:$G$198,"Family",統合決済履歴!$D$2:$D$198,"EUR",統合決済履歴!$F$2:$F$198,"COMPLETED",統合決済履歴!$J$2:$J$198,"共通",統合決済履歴!$K$2:$K$198,"2026-09") | D36: =SUMIFS(統合決済履歴!$C$2:$C$198,統合決済履歴!$G$2:$G$198,"Family",統合決済履歴!$D$2:$D$198,"JPY",統合決済履歴!$F$2:$F$198,"COMPLETED",統合決済履歴!$J$2:$J$198,"共通",統合決済履歴!$K$2:$K$198,"2026-09") | E36: =B36*設定!$B$3+C36*設定!$B$4+D36
A37: General | B37: =SUMIFS(統合決済履歴!$C$2:$C$198,統合決済履歴!$G$2:$G$198,"General",統合決済履歴!$D$2:$D$198,"GBP",統合決済履歴!$F$2:$F$198,"COMPLETED",統合決済履歴!$J$2:$J$198,"共通",統合決済履歴!$K$2:$K$198,"2026-09") | C37: =SUMIFS(統合決済履歴!$C$2:$C$198,統合決済履歴!$G$2:$G$198,"General",統合決済履歴!$D$2:$D$198,"EUR",統合決済履歴!$F$2:$F$198,"COMPLETED",統合決済履歴!$J$2:$J$198,"共通",統合決済履歴!$K$2:$K$198,"2026-09") | D37: =SUMIFS(統合決済履歴!$C$2:$C$198,統合決済履歴!$G$2:$G$198,"General",統合決済履歴!$D$2:$D$198,"JPY",統合決済履歴!$F$2:$F$198,"COMPLETED",統合決済履歴!$J$2:$J$198,"共通",統合決済履歴!$K$2:$K$198,"2026-09") | E37: =B37*設定!$B$3+C37*設定!$B$4+D37
A38: Groceries | B38: =SUMIFS(統合決済履歴!$C$2:$C$198,統合決済履歴!$G$2:$G$198,"Groceries",統合決済履歴!$D$2:$D$198,"GBP",統合決済履歴!$F$2:$F$198,"COMPLETED",統合決済履歴!$J$2:$J$198,"共通",統合決済履歴!$K$2:$K$198,"2026-09") | C38: =SUMIFS(統合決済履歴!$C$2:$C$198,統合決済履歴!$G$2:$G$198,"Groceries",統合決済履歴!$D$2:$D$198,"EUR",統合決済履歴!$F$2:$F$198,"COMPLETED",統合決済履歴!$J$2:$J$198,"共通",統合決済履歴!$K$2:$K$198,"2026-09") | D38: =SUMIFS(統合決済履歴!$C$2:$C$198,統合決済履歴!$G$2:$G$198,"Groceries",統合決済履歴!$D$2:$D$198,"JPY",統合決済履歴!$F$2:$F$198,"COMPLETED",統合決済履歴!$J$2:$J$198,"共通",統合決済履歴!$K$2:$K$198,"2026-09") | E38: =B38*設定!$B$3+C38*設定!$B$4+D38
A39: Money added | B39: =SUMIFS(統合決済履歴!$C$2:$C$198,統合決済履歴!$G$2:$G$198,"Money added",統合決済履歴!$D$2:$D$198,"GBP",統合決済履歴!$F$2:$F$198,"COMPLETED",統合決済履歴!$J$2:$J$198,"共通",統合決済履歴!$K$2:$K$198,"2026-09") | C39: =SUMIFS(統合決済履歴!$C$2:$C$198,統合決済履歴!$G$2:$G$198,"Money added",統合決済履歴!$D$2:$D$198,"EUR",統合決済履歴!$F$2:$F$198,"COMPLETED",統合決済履歴!$J$2:$J$198,"共通",統合決済履歴!$K$2:$K$198,"2026-09") | D39: =SUMIFS(統合決済履歴!$C$2:$C$198,統合決済履歴!$G$2:$G$198,"Money added",統合決済履歴!$D$2:$D$198,"JPY",統合決済履歴!$F$2:$F$198,"COMPLETED",統合決済履歴!$J$2:$J$198,"共通",統合決済履歴!$K$2:$K$198,"2026-09") | E39: =B39*設定!$B$3+C39*設定!$B$4+D39
A40: Personal care | B40: =SUMIFS(統合決済履歴!$C$2:$C$198,統合決済履歴!$G$2:$G$198,"Personal care",統合決済履歴!$D$2:$D$198,"GBP",統合決済履歴!$F$2:$F$198,"COMPLETED",統合決済履歴!$J$2:$J$198,"共通",統合決済履歴!$K$2:$K$198,"2026-09") | C40: =SUMIFS(統合決済履歴!$C$2:$C$198,統合決済履歴!$G$2:$G$198,"Personal care",統合決済履歴!$D$2:$D$198,"EUR",統合決済履歴!$F$2:$F$198,"COMPLETED",統合決済履歴!$J$2:$J$198,"共通",統合決済履歴!$K$2:$K$198,"2026-09") | D40: =SUMIFS(統合決済履歴!$C$2:$C$198,統合決済履歴!$G$2:$G$198,"Personal care",統合決済履歴!$D$2:$D$198,"JPY",統合決済履歴!$F$2:$F$198,"COMPLETED",統合決済履歴!$J$2:$J$198,"共通",統合決済履歴!$K$2:$K$198,"2026-09") | E40: =B40*設定!$B$3+C40*設定!$B$4+D40
A41: Shopping | B41: =SUMIFS(統合決済履歴!$C$2:$C$198,統合決済履歴!$G$2:$G$198,"Shopping",統合決済履歴!$D$2:$D$198,"GBP",統合決済履歴!$F$2:$F$198,"COMPLETED",統合決済履歴!$J$2:$J$198,"共通",統合決済履歴!$K$2:$K$198,"2026-09") | C41: =SUMIFS(統合決済履歴!$C$2:$C$198,統合決済履歴!$G$2:$G$198,"Shopping",統合決済履歴!$D$2:$D$198,"EUR",統合決済履歴!$F$2:$F$198,"COMPLETED",統合決済履歴!$J$2:$J$198,"共通",統合決済履歴!$K$2:$K$198,"2026-09") | D41: =SUMIFS(統合決済履歴!$C$2:$C$198,統合決済履歴!$G$2:$G$198,"Shopping",統合決済履歴!$D$2:$D$198,"JPY",統合決済履歴!$F$2:$F$198,"COMPLETED",統合決済履歴!$J$2:$J$198,"共通",統合決済履歴!$K$2:$K$198,"2026-09") | E41: =B41*設定!$B$3+C41*設定!$B$4+D41
A42: Transport | B42: =SUMIFS(統合決済履歴!$C$2:$C$198,統合決済履歴!$G$2:$G$198,"Transport",統合決済履歴!$D$2:$D$198,"GBP",統合決済履歴!$F$2:$F$198,"COMPLETED",統合決済履歴!$J$2:$J$198,"共通",統合決済履歴!$K$2:$K$198,"2026-09") | C42: =SUMIFS(統合決済履歴!$C$2:$C$198,統合決済履歴!$G$2:$G$198,"Transport",統合決済履歴!$D$2:$D$198,"EUR",統合決済履歴!$F$2:$F$198,"COMPLETED",統合決済履歴!$J$2:$J$198,"共通",統合決済履歴!$K$2:$K$198,"2026-09") | D42: =SUMIFS(統合決済履歴!$C$2:$C$198,統合決済履歴!$G$2:$G$198,"Transport",統合決済履歴!$D$2:$D$198,"JPY",統合決済履歴!$F$2:$F$198,"COMPLETED",統合決済履歴!$J$2:$J$198,"共通",統合決済履歴!$K$2:$K$198,"2026-09") | E42: =B42*設定!$B$3+C42*設定!$B$4+D42
A43: 合計 | B43: =SUM(B33:B42) | C43: =SUM(C33:C42) | D43: =SUM(D33:D42) | E43: =SUM(E33:E42)
...

Sheet トータル集計
A1: 全期間合計
A3: ■ 聖也
A4: カテゴリ | B4: GBP 合計 | C4: EUR 合計 | D4: JPY 合計 | E4: JPY換算合計
A5: Bills | B5: =SUMIFS(統合決済履歴!$C$2:$C$198,統合決済履歴!$G$2:$G$198,"Bills",統合決済履歴!$D$2:$D$198,"GBP",統合決済履歴!$F$2:$F$198,"COMPLETED",統合決済履歴!$J$2:$J$198,"聖也") | C5: =SUMIFS(統合決済履歴!$C$2:$C$198,統合決済履歴!$G$2:$G$198,"Bills",統合決済履歴!$D$2:$D$198,"EUR",統合決済履歴!$F$2:$F$198,"COMPLETED",統合決済履歴!$J$2:$J$198,"聖也") | D5: =SUMIFS(統合決済履歴!$C$2:$C$198,統合決済履歴!$G$2:$G$198,"Bills",統合決済履歴!$D$2:$D$198,"JPY",統合決済履歴!$F$2:$F$198,"COMPLETED",統合決済履歴!$J$2:$J$198,"聖也") | E5: =B5*設定!$B$3+C5*設定!$B$4+D5
A6: Eating out | B6: =SUMIFS(統合決済履歴!$C$2:$C$198,統合決済履歴!$G$2:$G$198,"Eating out",統合決済履歴!$D$2:$D$198,"GBP",統合決済履歴!$F$2:$F$198,"COMPLETED",統合決済履歴!$J$2:$J$198,"聖也") | C6: =SUMIFS(統合決済履歴!$C$2:$C$198,統合決済履歴!$G$2:$G$198,"Eating out",統合決済履歴!$D$2:$D$198,"EUR",統合決済履歴!$F$2:$F$198,"COMPLETED",統合決済履歴!$J$2:$J$198,"聖也") | D6: =SUMIFS(統合決済履歴!$C$2:$C$198,統合決済履歴!$G$2:$G$198,"Eating out",統合決済履歴!$D$2:$D$198,"JPY",統合決済履歴!$F$2:$F$198,"COMPLETED",統合決済履歴!$J$2:$J$198,"聖也") | E6: =B6*設定!$B$3+C6*設定!$B$4+D6
A7: Entertainment | B7: =SUMIFS(統合決済履歴!$C$2:$C$198,統合決済履歴!$G$2:$G$198,"Entertainment",統合決済履歴!$D$2:$D$198,"GBP",統合決済履歴!$F$2:$F$198,"COMPLETED",統合決済履歴!$J$2:$J$198,"聖也") | C7: =SUMIFS(統合決済履歴!$C$2:$C$198,統合決済履歴!$G$2:$G$198,"Entertainment",統合決済履歴!$D$2:$D$198,"EUR",統合決済履歴!$F$2:$F$198,"COMPLETED",統合決済履歴!$J$2:$J$198,"聖也") | D7: =SUMIFS(統合決済履歴!$C$2:$C$198,統合決済履歴!$G$2:$G$198,"Entertainment",統合決済履歴!$D$2:$D$198,"JPY",統合決済履歴!$F$2:$F$198,"COMPLETED",統合決済履歴!$J$2:$J$198,"聖也") | E7: =B7*設定!$B$3+C7*設定!$B$4+D7
A8: Family | B8: =SUMIFS(統合決済履歴!$C$2:$C$198,統合決済履歴!$G$2:$G$198,"Family",統合決済履歴!$D$2:$D$198,"GBP",統合決済履歴!$F$2:$F$198,"COMPLETED",統合決済履歴!$J$2:$J$198,"聖也") | C8: =SUMIFS(統合決済履歴!$C$2:$C$198,統合決済履歴!$G$2:$G$198,"Family",統合決済履歴!$D$2:$D$198,"EUR",統合決済履歴!$F$2:$F$198,"COMPLETED",統合決済履歴!$J$2:$J$198,"聖也") | D8: =SUMIFS(統合決済履歴!$C$2:$C$198,統合決済履歴!$G$2:$G$198,"Family",統合決済履歴!$D$2:$D$198,"JPY",統合決済履歴!$F$2:$F$198,"COMPLETED",統合決済履歴!$J$2:$J$198,"聖也") | E8: =B8*設定!$B$3+C8*設定!$B$4+D8
A9: General | B9: =SUMIFS(統合決済履歴!$C$2:$C$198,統合決済履歴!$G$2:$G$198,"General",統合決済履歴!$D$2:$D$198,"GBP",統合決済履歴!$F$2:$F$198,"COMPLETED",統合決済履歴!$J$2:$J$198,"聖也") | C9: =SUMIFS(統合決済履歴!$C$2:$C$198,統合決済履歴!$G$2:$G$198,"General",統合決済履歴!$D$2:$D$198,"EUR",統合決済履歴!$F$2:$F$198,"COMPLETED",統合決済履歴!$J$2:$J$198,"聖也") | D9: =SUMIFS(統合決済履歴!$C$2:$C$198,統合決済履歴!$G$2:$G$198,"General",統合決済履歴!$D$2:$D$198,"JPY",統合決済履歴!$F$2:$F$198,"COMPLETED",統合決済履歴!$J$2:$J$198,"聖也") | E9: =B9*設定!$B$3+C9*設定!$B$4+D9
A10: Groceries | B10: =SUMIFS(統合決済履歴!$C$2:$C$198,統合決済履歴!$G$2:$G$198,"Groceries",統合決済履歴!$D$2:$D$198,"GBP",統合決済履歴!$F$2:$F$198,"COMPLETED",統合決済履歴!$J$2:$J$198,"聖也") | C10: =SUMIFS(統合決済履歴!$C$2:$C$198,統合決済履歴!$G$2:$G$198,"Groceries",統合決済履歴!$D$2:$D$198,"EUR",統合決済履歴!$F$2:$F$198,"COMPLETED",統合決済履歴!$J$2:$J$198,"聖也") | D10: =SUMIFS(統合決済履歴!$C$2:$C$198,統合決済履歴!$G$2:$G$198,"Groceries",統合決済履歴!$D$2:$D$198,"JPY",統合決済履歴!$F$2:$F$198,"COMPLETED",統合決済履歴!$J$2:$J$198,"聖也") | E10: =B10*設定!$B$3+C10*設定!$B$4+D10
A11: Money added | B11: =SUMIFS(統合決済履歴!$C$2:$C$198,統合決済履歴!$G$2:$G$198,"Money added",統合決済履歴!$D$2:$D$198,"GBP",統合決済履歴!$F$2:$F$198,"COMPLETED",統合決済履歴!$J$2:$J$198,"聖也") | C11: =SUMIFS(統合決済履歴!$C$2:$C$198,統合決済履歴!$G$2:$G$198,"Money added",統合決済履歴!$D$2:$D$198,"EUR",統合決済履歴!$F$2:$F$198,"COMPLETED",統合決済履歴!$J$2:$J$198,"聖也") | D11: =SUMIFS(統合決済履歴!$C$2:$C$198,統合決済履歴!$G$2:$G$198,"Money added",統合決済履歴!$D$2:$D$198,"JPY",統合決済履歴!$F$2:$F$198,"COMPLETED",統合決済履歴!$J$2:$J$198,"聖也") | E11: =B11*設定!$B$3+C11*設定!$B$4+D11
A12: Personal care | B12: =SUMIFS(統合決済履歴!$C$2:$C$198,統合決済履歴!$G$2:$G$198,"Personal care",統合決済履歴!$D$2:$D$198,"GBP",統合決済履歴!$F$2:$F$198,"COMPLETED",統合決済履歴!$J$2:$J$198,"聖也") | C12: =SUMIFS(統合決済履歴!$C$2:$C$198,統合決済履歴!$G$2:$G$198,"Personal care",統合決済履歴!$D$2:$D$198,"EUR",統合決済履歴!$F$2:$F$198,"COMPLETED",統合決済履歴!$J$2:$J$198,"聖也") | D12: =SUMIFS(統合決済履歴!$C$2:$C$198,統合決済履歴!$G$2:$G$198,"Personal care",統合決済履歴!$D$2:$D$198,"JPY",統合決済履歴!$F$2:$F$198,"COMPLETED",統合決済履歴!$J$2:$J$198,"聖也") | E12: =B12*設定!$B$3+C12*設定!$B$4+D12
A13: Shopping | B13: =SUMIFS(統合決済履歴!$C$2:$C$198,統合決済履歴!$G$2:$G$198,"Shopping",統合決済履歴!$D$2:$D$198,"GBP",統合決済履歴!$F$2:$F$198,"COMPLETED",統合決済履歴!$J$2:$J$198,"聖也") | C13: =SUMIFS(統合決済履歴!$C$2:$C$198,統合決済履歴!$G$2:$G$198,"Shopping",統合決済履歴!$D$2:$D$198,"EUR",統合決済履歴!$F$2:$F$198,"COMPLETED",統合決済履歴!$J$2:$J$198,"聖也") | D13: =SUMIFS(統合決済履歴!$C$2:$C$198,統合決済履歴!$G$2:$G$198,"Shopping",統合決済履歴!$D$2:$D$198,"JPY",統合決済履歴!$F$2:$F$198,"COMPLETED",統合決済履歴!$J$2:$J$198,"聖也") | E13: =B13*設定!$B$3+C13*設定!$B$4+D13
A14: Transport | B14: =SUMIFS(統合決済履歴!$C$2:$C$198,統合決済履歴!$G$2:$G$198,"Transport",統合決済履歴!$D$2:$D$198,"GBP",統合決済履歴!$F$2:$F$198,"COMPLETED",統合決済履歴!$J$2:$J$198,"聖也") | C14: =SUMIFS(統合決済履歴!$C$2:$C$198,統合決済履歴!$G$2:$G$198,"Transport",統合決済履歴!$D$2:$D$198,"EUR",統合決済履歴!$F$2:$F$198,"COMPLETED",統合決済履歴!$J$2:$J$198,"聖也") | D14: =SUMIFS(統合決済履歴!$C$2:$C$198,統合決済履歴!$G$2:$G$198,"Transport",統合決済履歴!$D$2:$D$198,"JPY",統合決済履歴!$F$2:$F$198,"COMPLETED",統合決済履歴!$J$2:$J$198,"聖也") | E14: =B14*設定!$B$3+C14*設定!$B$4+D14
A15: 合計 | B15: =SUM(B5:B14) | C15: =SUM(C5:C14) | D15: =SUM(D5:D14) | E15: =SUM(E5:E14)
A17: ■ 愛弓
A18: カテゴリ | B18: GBP 合計 | C18: EUR 合計 | D18: JPY 合計 | E18: JPY換算合計
A19: Bills | B19: =SUMIFS(統合決済履歴!$C$2:$C$198,統合決済履歴!$G$2:$G$198,"Bills",統合決済履歴!$D$2:$D$198,"GBP",統合決済履歴!$F$2:$F$198,"COMPLETED",統合決済履歴!$J$2:$J$198,"愛弓") | C19: =SUMIFS(統合決済履歴!$C$2:$C$198,統合決済履歴!$G$2:$G$198,"Bills",統合決済履歴!$D$2:$D$198,"EUR",統合決済履歴!$F$2:$F$198,"COMPLETED",統合決済履歴!$J$2:$J$198,"愛弓") | D19: =SUMIFS(統合決済履歴!$C$2:$C$198,統合決済履歴!$G$2:$G$198,"Bills",統合決済履歴!$D$2:$D$198,"JPY",統合決済履歴!$F$2:$F$198,"COMPLETED",統合決済履歴!$J$2:$J$198,"愛弓") | E19: =B19*設定!$B$3+C19*設定!$B$4+D19
A20: Eating out | B20: =SUMIFS(統合決済履歴!$C$2:$C$198,統合決済履歴!$G$2:$G$198,"Eating out",統合決済履歴!$D$2:$D$198,"GBP",統合決済履歴!$F$2:$F$198,"COMPLETED",統合決済履歴!$J$2:$J$198,"愛弓") | C20: =SUMIFS(統合決済履歴!$C$2:$C$198,統合決済履歴!$G$2:$G$198,"Eating out",統合決済履歴!$D$2:$D$198,"EUR",統合決済履歴!$F$2:$F$198,"COMPLETED",統合決済履歴!$J$2:$J$198,"愛弓") | D20: =SUMIFS(統合決済履歴!$C$2:$C$198,統合決済履歴!$G$2:$G$198,"Eating out",統合決済履歴!$D$2:$D$198,"JPY",統合決済履歴!$F$2:$F$198,"COMPLETED",統合決済履歴!$J$2:$J$198,"愛弓") | E20: =B20*設定!$B$3+C20*設定!$B$4+D20
A21: Entertainment | B21: =SUMIFS(統合決済履歴!$C$2:$C$198,統合決済履歴!$G$2:$G$198,"Entertainment",統合決済履歴!$D$2:$D$198,"GBP",統合決済履歴!$F$2:$F$198,"COMPLETED",統合決済履歴!$J$2:$J$198,"愛弓") | C21: =SUMIFS(統合決済履歴!$C$2:$C$198,統合決済履歴!$G$2:$G$198,"Entertainment",統合決済履歴!$D$2:$D$198,"EUR",統合決済履歴!$F$2:$F$198,"COMPLETED",統合決済履歴!$J$2:$J$198,"愛弓") | D21: =SUMIFS(統合決済履歴!$C$2:$C$198,統合決済履歴!$G$2:$G$198,"Entertainment",統合決済履歴!$D$2:$D$198,"JPY",統合決済履歴!$F$2:$F$198,"COMPLETED",統合決済履歴!$J$2:$J$198,"愛弓") | E21: =B21*設定!$B$3+C21*設定!$B$4+D21
A22: Family | B22: =SUMIFS(統合決済履歴!$C$2:$C$198,統合決済履歴!$G$2:$G$198,"Family",統合決済履歴!$D$2:$D$198,"GBP",統合決済履歴!$F$2:$F$198,"COMPLETED",統合決済履歴!$J$2:$J$198,"愛弓") | C22: =SUMIFS(統合決済履歴!$C$2:$C$198,統合決済履歴!$G$2:$G$198,"Family",統合決済履歴!$D$2:$D$198,"EUR",統合決済履歴!$F$2:$F$198,"COMPLETED",統合決済履歴!$J$2:$J$198,"愛弓") | D22: =SUMIFS(統合決済履歴!$C$2:$C$198,統合決済履歴!$G$2:$G$198,"Family",統合決済履歴!$D$2:$D$198,"JPY",統合決済履歴!$F$2:$F$198,"COMPLETED",統合決済履歴!$J$2:$J$198,"愛弓") | E22: =B22*設定!$B$3+C22*設定!$B$4+D22
A23: General | B23: =SUMIFS(統合決済履歴!$C$2:$C$198,統合決済履歴!$G$2:$G$198,"General",統合決済履歴!$D$2:$D$198,"GBP",統合決済履歴!$F$2:$F$198,"COMPLETED",統合決済履歴!$J$2:$J$198,"愛弓") | C23: =SUMIFS(統合決済履歴!$C$2:$C$198,統合決済履歴!$G$2:$G$198,"General",統合決済履歴!$D$2:$D$198,"EUR",統合決済履歴!$F$2:$F$198,"COMPLETED",統合決済履歴!$J$2:$J$198,"愛弓") | D23: =SUMIFS(統合決済履歴!$C$2:$C$198,統合決済履歴!$G$2:$G$198,"General",統合決済履歴!$D$2:$D$198,"JPY",統合決済履歴!$F$2:$F$198,"COMPLETED",統合決済履歴!$J$2:$J$198,"愛弓") | E23: =B23*設定!$B$3+C23*設定!$B$4+D23
A24: Groceries | B24: =SUMIFS(統合決済履歴!$C$2:$C$198,統合決済履歴!$G$2:$G$198,"Groceries",統合決済履歴!$D$2:$D$198,"GBP",統合決済履歴!$F$2:$F$198,"COMPLETED",統合決済履歴!$J$2:$J$198,"愛弓") | C24: =SUMIFS(統合決済履歴!$C$2:$C$198,統合決済履歴!$G$2:$G$198,"Groceries",統合決済履歴!$D$2:$D$198,"EUR",統合決済履歴!$F$2:$F$198,"COMPLETED",統合決済履歴!$J$2:$J$198,"愛弓") | D24: =SUMIFS(統合決済履歴!$C$2:$C$198,統合決済履歴!$G$2:$G$198,"Groceries",統合決済履歴!$D$2:$D$198,"JPY",統合決済履歴!$F$2:$F$198,"COMPLETED",統合決済履歴!$J$2:$J$198,"愛弓") | E24: =B24*設定!$B$3+C24*設定!$B$4+D24
A25: Money added | B25: =SUMIFS(統合決済履歴!$C$2:$C$198,統合決済履歴!$G$2:$G$198,"Money added",統合決済履歴!$D$2:$D$198,"GBP",統合決済履歴!$F$2:$F$198,"COMPLETED",統合決済履歴!$J$2:$J$198,"愛弓") | C25: =SUMIFS(統合決済履歴!$C$2:$C$198,統合決済履歴!$G$2:$G$198,"Money added",統合決済履歴!$D$2:$D$198,"EUR",統合決済履歴!$F$2:$F$198,"COMPLETED",統合決済履歴!$J$2:$J$198,"愛弓") | D25: =SUMIFS(統合決済履歴!$C$2:$C$198,統合決済履歴!$G$2:$G$198,"Money added",統合決済履歴!$D$2:$D$198,"JPY",統合決済履歴!$F$2:$F$198,"COMPLETED",統合決済履歴!$J$2:$J$198,"愛弓") | E25: =B25*設定!$B$3+C25*設定!$B$4+D25
A26: Personal care | B26: =SUMIFS(統合決済履歴!$C$2:$C$198,統合決済履歴!$G$2:$G$198,"Personal care",統合決済履歴!$D$2:$D$198,"GBP",統合決済履歴!$F$2:$F$198,"COMPLETED",統合決済履歴!$J$2:$J$198,"愛弓") | C26: =SUMIFS(統合決済履歴!$C$2:$C$198,統合決済履歴!$G$2:$G$198,"Personal care",統合決済履歴!$D$2:$D$198,"EUR",統合決済履歴!$F$2:$F$198,"COMPLETED",統合決済履歴!$J$2:$J$198,"愛弓") | D26: =SUMIFS(統合決済履歴!$C$2:$C$198,統合決済履歴!$G$2:$G$198,"Personal care",統合決済履歴!$D$2:$D$198,"JPY",統合決済履歴!$F$2:$F$198,"COMPLETED",統合決済履歴!$J$2:$J$198,"愛弓") | E26: =B26*設定!$B$3+C26*設定!$B$4+D26
A27: Shopping | B27: =SUMIFS(統合決済履歴!$C$2:$C$198,統合決済履歴!$G$2:$G$198,"Shopping",統合決済履歴!$D$2:$D$198,"GBP",統合決済履歴!$F$2:$F$198,"COMPLETED",統合決済履歴!$J$2:$J$198,"愛弓") | C27: =SUMIFS(統合決済履歴!$C$2:$C$198,統合決済履歴!$G$2:$G$198,"Shopping",統合決済履歴!$D$2:$D$198,"EUR",統合決済履歴!$F$2:$F$198,"COMPLETED",統合決済履歴!$J$2:$J$198,"愛弓") | D27: =SUMIFS(統合決済履歴!$C$2:$C$198,統合決済履歴!$G$2:$G$198,"Shopping",統合決済履歴!$D$2:$D$198,"JPY",統合決済履歴!$F$2:$F$198,"COMPLETED",統合決済履歴!$J$2:$J$198,"愛弓") | E27: =B27*設定!$B$3+C27*設定!$B$4+D27
A28: Transport | B28: =SUMIFS(統合決済履歴!$C$2:$C$198,統合決済履歴!$G$2:$G$198,"Transport",統合決済履歴!$D$2:$D$198,"GBP",統合決済履歴!$F$2:$F$198,"COMPLETED",統合決済履歴!$J$2:$J$198,"愛弓") | C28: =SUMIFS(統合決済履歴!$C$2:$C$198,統合決済履歴!$G$2:$G$198,"Transport",統合決済履歴!$D$2:$D$198,"EUR",統合決済履歴!$F$2:$F$198,"COMPLETED",統合決済履歴!$J$2:$J$198,"愛弓") | D28: =SUMIFS(統合決済履歴!$C$2:$C$198,統合決済履歴!$G$2:$G$198,"Transport",統合決済履歴!$D$2:$D$198,"JPY",統合決済履歴!$F$2:$F$198,"COMPLETED",統合決済履歴!$J$2:$J$198,"愛弓") | E28: =B28*設定!$B$3+C28*設定!$B$4+D28
A29: 合計 | B29: =SUM(B19:B28) | C29: =SUM(C19:C28) | D29: =SUM(D19:D28) | E29: =SUM(E19:E28)
A31: ■ 共通
A32: カテゴリ | B32: GBP 合計 | C32: EUR 合計 | D32: JPY 合計 | E32: JPY換算合計
A33: Bills | B33: =SUMIFS(統合決済履歴!$C$2:$C$198,統合決済履歴!$G$2:$G$198,"Bills",統合決済履歴!$D$2:$D$198,"GBP",統合決済履歴!$F$2:$F$198,"COMPLETED",統合決済履歴!$J$2:$J$198,"共通") | C33: =SUMIFS(統合決済履歴!$C$2:$C$198,統合決済履歴!$G$2:$G$198,"Bills",統合決済履歴!$D$2:$D$198,"EUR",統合決済履歴!$F$2:$F$198,"COMPLETED",統合決済履歴!$J$2:$J$198,"共通") | D33: =SUMIFS(統合決済履歴!$C$2:$C$198,統合決済履歴!$G$2:$G$198,"Bills",統合決済履歴!$D$2:$D$198,"JPY",統合決済履歴!$F$2:$F$198,"COMPLETED",統合決済履歴!$J$2:$J$198,"共通") | E33: =B33*設定!$B$3+C33*設定!$B$4+D33
A34: Eating out | B34: =SUMIFS(統合決済履歴!$C$2:$C$198,統合決済履歴!$G$2:$G$198,"Eating out",統合決済履歴!$D$2:$D$198,"GBP",統合決済履歴!$F$2:$F$198,"COMPLETED",統合決済履歴!$J$2:$J$198,"共通") | C34: =SUMIFS(統合決済履歴!$C$2:$C$198,統合決済履歴!$G$2:$G$198,"Eating out",統合決済履歴!$D$2:$D$198,"EUR",統合決済履歴!$F$2:$F$198,"COMPLETED",統合決済履歴!$J$2:$J$198,"共通") | D34: =SUMIFS(統合決済履歴!$C$2:$C$198,統合決済履歴!$G$2:$G$198,"Eating out",統合決済履歴!$D$2:$D$198,"JPY",統合決済履歴!$F$2:$F$198,"COMPLETED",統合決済履歴!$J$2:$J$198,"共通") | E34: =B34*設定!$B$3+C34*設定!$B$4+D34
A35: Entertainment | B35: =SUMIFS(統合決済履歴!$C$2:$C$198,統合決済履歴!$G$2:$G$198,"Entertainment",統合決済履歴!$D$2:$D$198,"GBP",統合決済履歴!$F$2:$F$198,"COMPLETED",統合決済履歴!$J$2:$J$198,"共通") | C35: =SUMIFS(統合決済履歴!$C$2:$C$198,統合決済履歴!$G$2:$G$198,"Entertainment",統合決済履歴!$D$2:$D$198,"EUR",統合決済履歴!$F$2:$F$198,"COMPLETED",統合決済履歴!$J$2:$J$198,"共通") | D35: =SUMIFS(統合決済履歴!$C$2:$C$198,統合決済履歴!$G$2:$G$198,"Entertainment",統合決済履歴!$D$2:$D$198,"JPY",統合決済履歴!$F$2:$F$198,"COMPLETED",統合決済履歴!$J$2:$J$198,"共通") | E35: =B35*設定!$B$3+C35*設定!$B$4+D35
A36: Family | B36: =SUMIFS(統合決済履歴!$C$2:$C$198,統合決済履歴!$G$2:$G$198,"Family",統合決済履歴!$D$2:$D$198,"GBP",統合決済履歴!$F$2:$F$198,"COMPLETED",統合決済履歴!$J$2:$J$198,"共通") | C36: =SUMIFS(統合決済履歴!$C$2:$C$198,統合決済履歴!$G$2:$G$198,"Family",統合決済履歴!$D$2:$D$198,"EUR",統合決済履歴!$F$2:$F$198,"COMPLETED",統合決済履歴!$J$2:$J$198,"共通") | D36: =SUMIFS(統合決済履歴!$C$2:$C$198,統合決済履歴!$G$2:$G$198,"Family",統合決済履歴!$D$2:$D$198,"JPY",統合決済履歴!$F$2:$F$198,"COMPLETED",統合決済履歴!$J$2:$J$198,"共通") | E36: =B36*設定!$B$3+C36*設定!$B$4+D36
A37: General | B37: =SUMIFS(統合決済履歴!$C$2:$C$198,統合決済履歴!$G$2:$G$198,"General",統合決済履歴!$D$2:$D$198,"GBP",統合決済履歴!$F$2:$F$198,"COMPLETED",統合決済履歴!$J$2:$J$198,"共通") | C37: =SUMIFS(統合決済履歴!$C$2:$C$198,統合決済履歴!$G$2:$G$198,"General",統合決済履歴!$D$2:$D$198,"EUR",統合決済履歴!$F$2:$F$198,"COMPLETED",統合決済履歴!$J$2:$J$198,"共通") | D37: =SUMIFS(統合決済履歴!$C$2:$C$198,統合決済履歴!$G$2:$G$198,"General",統合決済履歴!$D$2:$D$198,"JPY",統合決済履歴!$F$2:$F$198,"COMPLETED",統合決済履歴!$J$2:$J$198,"共通") | E37: =B37*設定!$B$3+C37*設定!$B$4+D37
A38: Groceries | B38: =SUMIFS(統合決済履歴!$C$2:$C$198,統合決済履歴!$G$2:$G$198,"Groceries",統合決済履歴!$D$2:$D$198,"GBP",統合決済履歴!$F$2:$F$198,"COMPLETED",統合決済履歴!$J$2:$J$198,"共通") | C38: =SUMIFS(統合決済履歴!$C$2:$C$198,統合決済履歴!$G$2:$G$198,"Groceries",統合決済履歴!$D$2:$D$198,"EUR",統合決済履歴!$F$2:$F$198,"COMPLETED",統合決済履歴!$J$2:$J$198,"共通") | D38: =SUMIFS(統合決済履歴!$C$2:$C$198,統合決済履歴!$G$2:$G$198,"Groceries",統合決済履歴!$D$2:$D$198,"JPY",統合決済履歴!$F$2:$F$198,"COMPLETED",統合決済履歴!$J$2:$J$198,"共通") | E38: =B38*設定!$B$3+C38*設定!$B$4+D38
A39: Money added | B39: =SUMIFS(統合決済履歴!$C$2:$C$198,統合決済履歴!$G$2:$G$198,"Money added",統合決済履歴!$D$2:$D$198,"GBP",統合決済履歴!$F$2:$F$198,"COMPLETED",統合決済履歴!$J$2:$J$198,"共通") | C39: =SUMIFS(統合決済履歴!$C$2:$C$198,統合決済履歴!$G$2:$G$198,"Money added",統合決済履歴!$D$2:$D$198,"EUR",統合決済履歴!$F$2:$F$198,"COMPLETED",統合決済履歴!$J$2:$J$198,"共通") | D39: =SUMIFS(統合決済履歴!$C$2:$C$198,統合決済履歴!$G$2:$G$198,"Money added",統合決済履歴!$D$2:$D$198,"JPY",統合決済履歴!$F$2:$F$198,"COMPLETED",統合決済履歴!$J$2:$J$198,"共通") | E39: =B39*設定!$B$3+C39*設定!$B$4+D39
A40: Personal care | B40: =SUMIFS(統合決済履歴!$C$2:$C$198,統合決済履歴!$G$2:$G$198,"Personal care",統合決済履歴!$D$2:$D$198,"GBP",統合決済履歴!$F$2:$F$198,"COMPLETED",統合決済履歴!$J$2:$J$198,"共通") | C40: =SUMIFS(統合決済履歴!$C$2:$C$198,統合決済履歴!$G$2:$G$198,"Personal care",統合決済履歴!$D$2:$D$198,"EUR",統合決済履歴!$F$2:$F$198,"COMPLETED",統合決済履歴!$J$2:$J$198,"共通") | D40: =SUMIFS(統合決済履歴!$C$2:$C$198,統合決済履歴!$G$2:$G$198,"Personal care",統合決済履歴!$D$2:$D$198,"JPY",統合決済履歴!$F$2:$F$198,"COMPLETED",統合決済履歴!$J$2:$J$198,"共通") | E40: =B40*設定!$B$3+C40*設定!$B$4+D40
A41: Shopping | B41: =SUMIFS(統合決済履歴!$C$2:$C$198,統合決済履歴!$G$2:$G$198,"Shopping",統合決済履歴!$D$2:$D$198,"GBP",統合決済履歴!$F$2:$F$198,"COMPLETED",統合決済履歴!$J$2:$J$198,"共通") | C41: =SUMIFS(統合決済履歴!$C$2:$C$198,統合決済履歴!$G$2:$G$198,"Shopping",統合決済履歴!$D$2:$D$198,"EUR",統合決済履歴!$F$2:$F$198,"COMPLETED",統合決済履歴!$J$2:$J$198,"共通") | D41: =SUMIFS(統合決済履歴!$C$2:$C$198,統合決済履歴!$G$2:$G$198,"Shopping",統合決済履歴!$D$2:$D$198,"JPY",統合決済履歴!$F$2:$F$198,"COMPLETED",統合決済履歴!$J$2:$J$198,"共通") | E41: =B41*設定!$B$3+C41*設定!$B$4+D41
A42: Transport | B42: =SUMIFS(統合決済履歴!$C$2:$C$198,統合決済履歴!$G$2:$G$198,"Transport",統合決済履歴!$D$2:$D$198,"GBP",統合決済履歴!$F$2:$F$198,"COMPLETED",統合決済履歴!$J$2:$J$198,"共通") | C42: =SUMIFS(統合決済履歴!$C$2:$C$198,統合決済履歴!$G$2:$G$198,"Transport",統合決済履歴!$D$2:$D$198,"EUR",統合決済履歴!$F$2:$F$198,"COMPLETED",統合決済履歴!$J$2:$J$198,"共通") | D42: =SUMIFS(統合決済履歴!$C$2:$C$198,統合決済履歴!$G$2:$G$198,"Transport",統合決済履歴!$D$2:$D$198,"JPY",統合決済履歴!$F$2:$F$198,"COMPLETED",統合決済履歴!$J$2:$J$198,"共通") | E42: =B42*設定!$B$3+C42*設定!$B$4+D42
A43: 合計 | B43: =SUM(B33:B42) | C43: =SUM(C33:C42) | D43: =SUM(D33:D42) | E43: =SUM(E33:E42)
...
